Workbook

Sheet Dropdown_Helper
A1: A - Sofort kontaktieren | B1: Keine Website gefunden | C1: Kein Online-Booking gefunden | D1: Hoch | E1: Quick Win | F1: Neu | G1: Offen | H1: Offiziell bestaetigt
A2: B - Gute Chance | B2: Schwache Website | C2: Booking nur ueber WhatsApp/Telefon | D2: Mittel | E2: Premium Upgrade | F2: Zu pruefen | G2: In Verhandlung | H2: Oeffentlich gelistet
A3: C - Spaeter pruefen | B3: Website vorhanden | C3: Einfaches Booking vorhanden | D3: Niedrig | E3: Local SEO Fix | F3: Kontaktiert | G3: Gewonnen | H3: Manuell zu pruefen
A4: D - Niedrige Prioritaet | B4: Gute Website | C4: Starkes Booking vorhanden | E4: Booking Upgrade | F4: Follow-up noetig | G4: Verloren
E5: Nicht priorisiert | F5: Termin vereinbart
F6: Angebot gesendet
F7: Gewonnen
F8: Verloren
F9: Nicht passend

Sheet Uebersicht
B2: Alanya Barber Shop - Lead Dashboard
B3: B2B Marktanalyse & Kundenakquise | Stand: Juni 2026
B5: =COUNTA('Lead CRM'!A2:A51) -> 50 | D5: =COUNTIF('Lead CRM'!A2:A51,"A*") -> 11 | F5: =COUNTIF('Lead CRM'!L2:L51,"Keine Website gefunden") -> 41 | H5: =COUNTIF('Lead CRM'!M2:M51,"Kein Online-Booking gefunden") -> 42
B6: Gesamt Leads | D6: A-Prioritaet | F6: Ohne Website | H6: Ohne Booking
B8: =COUNTIF('Lead CRM'!R2:R51,"Kontaktiert")+COUNTIF('Lead CRM'!R2:R51,"Termin vereinbart")+COUNTIF('Lead CRM'!R2:R51,"Angebot gesendet") -> 0 | D8: =COUNTIF('Lead CRM'!R2:R51,"Follow-up noetig") -> 0 | F8: =COUNTIF('Lead CRM'!U2:U51,"Gewonnen") -> 0 | H8: =SUM('Lead CRM'!V2:V51) -> 57300
B9: Kontaktiert | D9: Follow-ups | F9: Gewonnen | H9: Potenzial (EUR)
B11: Markt-Fazit & Opportunity
B12: Die Marktanalyse Alanya zeigt eine exzellente Opportunity: • Marktgroesse: Geschätzt 250-450 Barbier-/Kuafoer-Betriebe in Alanya • Digital Gap: 80-90% haben keine Website, 95%+ kein Online-Booking • Tourismus: 4,5-5 Mio. Touristen/Jahr, 30.000+ auslaendische Residenten • TAM ~127.000 EUR | SAM ~71.000 EUR | SOM (Jahr 1) ~7.000 EUR • Strategie: Touristen-Bezirke zuerst (Mahmutlar, Oba, Merkez) • Einstieg: Starterpakete 95-150 EUR sind sehr erschwinglich
B19: Empfohlene Naechste Schritte
B20: 1. Sofort | C20: A-Prioritaet Leads kontaktieren (11 Betriebe) | H20: Heute
B21: 2. Diese Woche | C21: Mahmutlar & Oba besuchen - 8 Top-Leads | H21: Tag 1-3
B22: 3. Termine | C22: 3-5 Pilotkunden fuer verguenstigte Websites gewinnen | H22: Woche 1-2
B23: 4. Esnaf Odasi | C23: Alanya Esnaf Odasi anrufen (+90 242 513 18 52) | H23: Woche 1
B24: 5. Pitch | C24: Tuerkischsprachige Verkaufsunterlagen mit ROI-Beispielen | H24: Woche 1-2
B26: Leads nach Bezirk
B27: Bezirk | C27: Anzahl | D27: Ohne Website | E27: Ohne Booking | F27: Top-Prio | G27: Empfohlener Tag
B28: Saray (Merkez) | C28: 15 | D28: ~14 | E28: 15 | F28: B/C | G28: Tag 1 Nachmittag
B29: Sekerhane | C29: 8 | D29: ~7 | E29: 8 | F29: A | G29: Tag 1 Vormittag
B30: Oba | C30: 5 | D30: ~4 | E30: 5 | F30: A | G30: Tag 2 Vormittag
B31: Gueller Pınari | C31: 4 | D31: ~3 | E31: 4 | F31: A | G31: Tag 2 Nachmittag
B32: Mahmutlar | C32: 3 | D32: ~2 | E32: 3 | F32: A | G32: Tag 3 Vormittag
B33: Cikcilli | C33: 3 | D33: ~2 | E33: 3 | F33: B | G33: Tag 3 Nachmittag
B34: Hacet | C34: 3 | D34: ~2 | E34: 3 | F34: B | G34: Tag 4 Vormittag
B35: Kizlar Pınari | C35: 2 | D35: ~1 | E35: 2 | F35: B | G35: Tag 4 Nachmittag
B36: Konakli | C36: 2 | D36: ~1 | E36: 2 | F36: B | G36: Tag 5 Vormittag
B37: Tosmur | C37: 2 | D37: ~1 | E37: 2 | F37: B | G37: Tag 5 Nachmittag
B38: Sonstige | C38: 3 | D38: ~2 | E38: 3 | F38: C | G38: Spaeter

Sheet Lead CRM
A1: Prioritaet | B1: Route | C1: Bezirk | D1: Barber / Geschaeft | E1: Adresse | F1: Telefon / WhatsApp | G1: Website | H1: Maps / Directory | I1: Instagram | J1: Bewertung | K1: Services | L1: Website-Status | M1: Booking-Status | N1: SEO-Potenzial | O1: Hauptproblem | P1: Empfohlenes Angebot | Q1: Segment | R1: Kontaktstatus | S1: Letzter Kontakt | T1: Naechster Schritt | U1: Conversion | V1: Umsatzpotenzial EUR | W1: Quelle | X1: Verifizierung | Y1: Notizen
A2: A - Sofort | B2: 1 | C2: Mahmutlar | D2: King Barbershop | E2: Nexus Apart No:20 119 St Mahmutlar | F2: +90 535 355 92 66 | G2: https://kingbarbershop.com.tr | H2: Yandex Maps | I2: Nicht gefunden | J2: 5.0/5 (27 Google) | K2: Signature kesim sicak havlu sakal sekillendirme | L2: Website vorhanden | M2: Booking nur über WhatsApp/Telefon | N2: Mittel | O2: Keine Online-Terminbuchung | P2: Booking + Google Business | Q2: Premium Upgrade | R2: Neu | T2: Instagram/Telefon kontaktieren | U2: Offen | V2: 1500 | W2: Yandex Google | X2: Offiziell bestätigt | Y2: Premium Barbier
A3: A - Sofort | B3: 1 | C3: Mahmutlar | D3: Caglar Kuafor | E3: Cumhuriyet Mah Mehmet Cakir Cd 14/C | F3: +90 538 501 65 04 | G3: Nicht gefunden | H3: Alanya GO | I3: Nicht gefunden | J3: 3.0/5 (13) | K3: Sac kesimi sakal bakimi modern styling | L3: Keine Website gefunden | M3: Kein Online-Booking gefunden | N3: Hoch | O3: Keine Website keine Online-Präsenz | P3: Komplettpaket Website + Booking + SEO | Q3: Quick Win | R3: Neu | T3: Vor-Ort-Besuch | U3: Offen | V3: 2000 | W3: Alanya GO Yandex | X3: Oeffentlich gelistet | Y3: 15+ Jahre Erfahrung
A4: A - Sofort | B4: 1 | C4: Mahmutlar | D4: Kuafor Tevfik | E4: Mahmutlar Mah 248 Sok No:11/A | F4: +90 533 231 35 51 | G4: Nicht gefunden | H4: Yandex Maps | I4: Nicht gefunden | J4: 4.4/5 (17) | K4: Erkek sac kesimi sakal bakimi 24h | L4: Keine Website gefunden | M4: Kein Online-Booking gefunden | N4: Hoch | O4: Keine Website trotz 24h-Betrieb | P4: Website + Online-Booking + Google | Q4: Quick Win | R4: Neu | T4: Telefonisch kontaktieren | U4: Offen | V4: 1800 | W4: Yandex Maps | X4: Oeffentlich gelistet | Y4: 24h geoeffnet - einzigartig
A5: A - Sofort | B5: 2 | C5: Oba | D5: Kerim Guven Barber Club | E5: Oba Eski Gazipasa Cd No:25/B | F5: +90 539 524 99 88 | G5: https://kerimguven.com | H5: Explore Alanya | I5: Nicht gefunden | J5: 5.0/5 (254 Yandex) 4.7/5 (474) | K5: Fade taper beard coloring facial manikuer | L5: Gute Website | M5: Starkes Booking vorhanden | N5: Mittel | O5: Website existiert SEO/GEO ausbaufaehig | P5: SEO/GEO Optimierung + AI Chat | Q5: Premium Upgrade | R5: Neu | T5: E-Mail mit SEO-Analyse | U5: Offen | V5: 3000 | W5: Explore Alanya Yandex | X5: Offiziell bestaetigt | Y5: Premium-Salon Multi-Currency VIP
A6: A - Sofort | B6: 2 | C6: Oba | D6: Hair Studio Eyuep Sahin | E6: Karakuş Sok Fabrika Cd 2c/a Oba | F6: +90 530 402 94 90 | G6: Nicht gefunden | H6: Alanya GO | I6: Nicht gefunden | J6: 4.6/5 (9) 5.0/5 (5) | K6: Sac kesimi ombre sombre roefle keratin | L6: Keine Website gefunden | M6: Kein Online-Booking gefunden | N6: Hoch | O6: Keine Website trotz exzellenter Bewertungen | P6: Komplettpaket Website + Booking + Gallery | Q6: Quick Win | R6: Neu | T6: Vor-Ort-Besuch | U6: Offen | V6: 2500 | W6: Alanya GO Yandex | X6: Oeffentlich gelistet | Y6: Top-Bewertungen Coloring-Spezialist
A7: A - Sofort | B7: 2 | C7: Oba | D7: Yusuf Berber Salonu | E7: Oba Mah Carsamba Cad 61/3 | F7: +90 535 330 13 72 | G7: https://yusufhairsalon.com | H7: Yandex Maps | I7: Referenziert | J7: 5.0/5 (14) | K7: Coloring balayage extensions keratin | L7: Website vorhanden | M7: Kein Online-Booking gefunden | N7: Hoch | O7: Website vorhanden aber kein Booking | P7: Booking-Upgrade + AI-Chat | Q7: Booking Upgrade | R7: Neu | T7: Website-Analyse senden | U7: Offen | V7: 2000 | W7: Yandex Website | X7: Oeffentlich gelistet | Y7: Auch Herren-Services Instagram aktiv
A8: B - Gute Chance | B8: 2 | C8: Oba | D8: Kardesler Berber | E8: Oba Mah Carsamba Cad 62A | F8: +90 538 523 51 78 | G8: Nicht gefunden | H8: Yandex Maps | I8: Nicht gefunden | J8: 4.3/5 (4) | K8: Sac kesimi traş sakal bakimi | L8: Keine Website gefunden | M8: Kein Online-Booking gefunden | N8: Mittel | O8: Keine Online-Präsenz | P8: Starterpaket Website + Google Business | Q8: Local SEO Fix | R8: Neu | T8: Vor-Ort-Besuch | U8: Offen | V8: 1200 | W8: Yandex Maps | X8: Oeffentlich gelistet
A9: B - Gute Chance | B9: 2 | C9: Oba | D9: FK Kuafor | E9: Oba Mah Carsamba Cad 21 | F9: +90 536 782 33 62 | G9: Nicht gefunden | H9: Yandex Maps | I9: Nicht gefunden | J9: Yandex gelistet | K9: Sac kesimi sakal bakimi | L9: Keine Website gefunden | M9: Kein Online-Booking gefunden | N9: Mittel | O9: Keine Online-Präsenz | P9: Starterpaket | Q9: Local SEO Fix | R9: Neu | T9: Vor-Ort-Besuch | U9: Offen | V9: 1000 | W9: Yandex Maps | X9: Oeffentlich gelistet | Y9: Schließt 21:00
A10: A - Sofort | B10: 3 | C10: Sekerhane | D10: Ilyas Unver Hairdesigner | E10: Sekerhane Sevket Tokus CD No:56 | F10: +90 507 156 50 30 | G10: https://www.ilyasunver.com | H10: Yandex Maps | I10: @hairdesigner_ilyasunver | J10: 4.5/5 (Seit 2010) | K10: Anatomisches Schneiden Sakal Traş Maske Keratin | L10: Website vorhanden | M10: Booking nur über WhatsApp/Telefon | N10: Mittel | O10: Nur WhatsApp-Booking SEO ausbaufaehig | P10: Online-Booking-System + AI Chat | Q10: Premium Upgrade | R10: Neu | T10: Instagram DM | U10: Offen | V10: 2500 | W10: Website Yandex | X10: Offiziell bestaetigt | Y10: Seit 2010 Instagram bestaetigt VIP
A11: A - Sofort | B11: 3 | C11: Sekerhane | D11: Kuafoer By Oezcan | E11: Sekerhane Mah Kaymakli Sok No:7 | F11: Telefon auf Yandex | G11: Nicht gefunden | H11: Yandex Maps | I11: Nicht gefunden | J11: 5.0/5 (92 Barberhead) | K11: Haarschnitt Bart Waschen Massage Hausbesuche | L11: Keine Website gefunden | M11: Kein Online-Booking gefunden | N11: Hoch | O11: Top-Bewertungen aber keine Website | P11: Komplettpaket Website + Booking + SEO | Q11: Quick Win | R11: Neu | T11: Priorisierter Vor-Ort-Besuch | U11: Offen | V11: 2500 | W11: Barberhead Yandex | X11: Oeffentlich gelistet | Y11: Hausbesuch russischsprachiges Personal
A12: B - Gute Chance | B12: 3 | C12: Sekerhane | D12: Fi Still Erkek Kuafoerue | E12: Sekerhane Cinal Sk No:16 D:b | F12: +90 545 619 62 20 | G12: Nicht gefunden | H12: Barberhead | I12: Nicht gefunden | J12: 4.9/5 (27) | K12: Herrenhaarschnitt Bartpflege | L12: Keine Website gefunden | M12: Kein Online-Booking gefunden | N12: Hoch | O12: Sehr gute Bewertung keine digitale Präsenz | P12: Website + Google Business + Review-Mgmt | Q12: Quick Win | R12: Neu | T12: Telefonisch vorstellen | U12: Offen | V12: 1800 | W12: Barberhead Alanya.gen.tr | X12: Oeffentlich gelistet
A13: B - Gute Chance | B13: 3 | C13: Sekerhane | D13: Keskin Makas Erkek Kuafoerue | E13: Sekerhane Mah Rektoer Sipahioglu Sok 4 | F13: Nicht gefunden | G13: Nicht gefunden | H13: Yandex Maps | I13: Nicht gefunden | J13: 5.0/5 (1) | K13: Herrenhaarschnitt Rasur | L13: Keine Website gefunden | M13: Kein Online-Booking gefunden | N13: Mittel | O13: Minimale Online-Präsenz | P13: Starterpaket | Q13: Local SEO Fix | R13: Neu | T13: Vor-Ort-Besuch | U13: Offen | V13: 800 | W13: Yandex Maps | X13: Manuell zu pruefen
A14: B - Gute Chance | B14: 3 | C14: Sekerhane | D14: Mehmet Gabakci | E14: Sekerhane Kasapoglu Sk No:19 | F14: Nicht gefunden | G14: Nicht gefunden | H14: Barberhead | I14: Nicht gefunden | J14: 4.5/5 (4) | K14: Herrenhaarschnitt Bartpflege | L14: Keine Website gefunden | M14: Kein Online-Booking gefunden | N14: Mittel | O14: Keine Website | P14: Starterpaket | Q14: Local SEO Fix | R14: Neu | T14: Vor-Ort-Besuch | U14: Offen | V14: 800 | W14: Barberhead | X14: Oeffentlich gelistet
A15: B - Gute Chance | B15: 3 | C15: Sekerhane | D15: Yanki Erkek Berberi | E15: Sekerhane Tevfikiye Cad 28 | F15: Nicht gefunden | G15: Nicht gefunden | H15: Barberhead | I15: Nicht gefunden | J15: 5.0/5 (1) | K15: Herrenhaarschnitt Bartpflege | L15: Keine Website gefunden | M15: Kein Online-Booking gefunden | N15: Mittel | O15: Keine Website | P15: Starterpaket | Q15: Local SEO Fix | R15: Neu | T15: Vor-Ort-Besuch | U15: Offen | V15: 800 | W15: Barberhead | X15: Oeffentlich gelistet
A16: C - Spaeter | B16: 3 | C16: Sekerhane | D16: Koesk Berber | E16: Sekerhane Sevket Tokus Cd 41 | F16: Nicht gefunden | G16: Nicht gefunden | H16: Barberhead | I16: Nicht gefunden | J16: 5.0/5 (2) | K16: Herrenhaarschnitt Bartpflege | L16: Keine Website gefunden | M16: Kein Online-Booking gefunden | N16: Mittel | O16: Keine Website | P16: Starterpaket | Q16: Nicht priorisiert | R16: Neu | T16: Spaeter pruefen | U16: Offen | V16: 600 | W16: Barberhead | X16: Oeffentlich gelistet
A17: C - Spaeter | B17: 3 | C17: Sekerhane | D17: Aydin Erkek Kuafoerue | E17: Sekerhane 07400 Alanya | F17: Nicht gefunden | G17: Nicht gefunden | H17: Alanya-GO | I17: Nicht gefunden | J17: Alanya-GO gelistet | K17: Herrenhaarschnitt Bartpflege | L17: Keine Website gefunden | M17: Kein Online-Booking gefunden | N17: Mittel | O17: Keine Online-Präsenz | P17: Starterpaket | Q17: Nicht priorisiert | R17: Neu | T17: Spaeter pruefen | U17: Offen | V17: 500 | W17: Alanya-GO | X17: Manuell zu pruefen | Y17: Adresse unklar
A18: A - Sofort | B18: 4 | C18: Güller Pinari | D18: Mavi Deniz Erkek Kuafoerue | E18: Güller Pinari Mah Navalioglu Sok 9/A | F18: +90 536 584 94 64 | G18: Nicht gefunden | H18: Yandex Maps | I18: Nicht gefunden | J18: 4.9/5 (92 Yandex) | K18: Herrenhaarschnitt Bart Rasur | L18: Keine Website gefunden | M18: Kein Online-Booking gefunden | N18: Hoch | O18: Top-Bewertungen sehr beliebt keine Website | P18: Komplettpaket Website + Booking + SEO | Q18: Quick Win | R18: Neu | T18: Telefonisch kontaktieren | U18: Offen | V18: 2500 | W18: Yandex Alanya.gen.tr | X18: Oeffentlich gelistet | Y18: Taeglich 08:30-21:00 sehr beliebt
A19: B - Gute Chance | B19: 4 | C19: Güller Pinari | D19: Prime Alanya Barber Shop | E19: Kizlar Pinari Mah Yildiz Sok No:3 | F19: +90 539 355 60 50 | G19: Nicht gefunden | H19: Yandex Maps | I19: Nicht gefunden | J19: 5.0/5 (32) | K19: Haarschnitt Kinder Color Highlights Bart Hausbesuch | L19: Keine Website gefunden | M19: Kein Online-Booking gefunden | N19: Hoch | O19: Gute Bewertungen Hausbesuch-Service | P19: Website + Booking-System | Q19: Quick Win | R19: Neu | T19: WhatsApp kontaktieren | U19: Offen | V19: 2000 | W19: Yandex Maps | X19: Oeffentlich gelistet | Y19: Hausbesuch Behindertenparkplatz WLAN
A20: B - Gute Chance | B20: 4 | C20: Güller Pinari | D20: Bora Kuafor | E20: Kadipasa Hayate Hanim Cad No:12 | F20: (0242) 511 77 95 | G20: Nicht gefunden | H20: Yandex Maps | I20: Nicht gefunden | J20: Gelistet | K20: Herren-/Damenhaarschnitt | L20: Keine Website gefunden | M20: Kein Online-Booking gefunden | N20: Mittel | O20: Keine Website | P20: Starterpaket | Q20: Local SEO Fix | R20: Neu | T20: Vor-Ort-Besuch | U20: Offen | V20: 1000 | W20: Yandex 07haber | X20: Oeffentlich gelistet
A21: B - Gute Chance | B21: 4 | C21: Güller Pinari | D21: Club Barber Tan | E21: Güller Pinari Mah Yenilmez Cad 48F | F21: +90 506 343 62 95 | G21: Nicht gefunden | H21: Barberhead | I21: Nicht gefunden | J21: 4.2/5 (5) | K21: Herrenhaarschnitt Bartpflege | L21: Keine Website gefunden | M21: Kein Online-Booking gefunden | N21: Mittel | O21: Keine Website | P21: Starterpaket | Q21: Local SEO Fix | R21: Neu | T21: Vor-Ort-Besuch | U21: Offen | V21: 1000 | W21: Barberhead Yandex | X21: Oeffentlich gelistet
A22: A - Sofort | B22: 5 | C22: Saray | D22: Viking Hair Club | E22: Saray Mah Midye Sk No:9 | F22: +90 506 934 87 26 | G22: Nicht gefunden | H22: Yandex Maps | I22: Referenziert | J22: 4.9/5 (35) | K22: Cut Color Balayage Keratin Extensions Makeup | L22: Schwache Website | M22: Booking nur über WhatsApp/Telefon | N22: Hoch | O22: Nur Wheree-Menue kein eigenes Booking | P22: Eigene Website + Booking + AI Chat | Q22: Premium Upgrade | R22: Neu | T22: Kontakt über Phone | U22: Offen | V22: 2500 | W22: Explore Alanya Yandex | X22: Oeffentlich gelistet | Y22: Free Pick-up Multi-Currency EN/RU
A23: A - Sofort | B23: 5 | C23: Saray | D23: Goelgen Hair Beauty | E23: Saray Mah Cangal Sok | F23: Nicht gefunden | G23: Google Maps | H23: Nicht gefunden | I23: 4.7/5 (347 Google) | J23: Haarschnitt Color Bart Pflege | K23: Keine Website gefunden | L23: Kein Online-Booking gefunden | M23: Hoch | N23: 347 Reviews sehr bekannt keine Website | O23: Komplettpaket + Review-Management | P23: Quick Win | Q23: Neu | S23: Vor-Ort-Besuch | T23: Offen | U23: 3000 | V23: Google Maps | W23: Oeffentlich gelistet | X23: 347 Reviews - sehr bekannt
A24: B - Gute Chance | B24: 5 | C24: Saray | D24: Aydin Barbers | E24: Saray Mah Cangal Sok No:5/B | F24: Nicht gefunden | G24: Nicht gefunden | H24: Barberhead | I24: Nicht gefunden | J24: 5.0/5 (25) | K24: Herrenhaarschnitt Bartpflege | L24: Keine Website gefunden | M24: Kein Online-Booking gefunden | N24: Hoch | O24: Sehr gute Bewertung keine Website | P24: Website + Google Business | Q24: Quick Win | R24: Neu | T24: Vor-Ort-Besuch | U24: Offen | V24: 1500 | W24: Barberhead | X24: Oeffentlich gelistet
A25: B - Gute Chance | B25: 5 | C25: Saray | D25: Yilmaz Berber | E25: Saray Damlatas Cd No:56/C | F25: +90 242 512 06 06 | G25: Nicht gefunden | H25: Yandex Maps | I25: Nicht gefunden | J25: 4.2/5 (4) | K25: Erkek sac kesimi sakal tiras cilt bakimi | L25: Keine Website gefunden | M25: Kein Online-Booking gefunden | N25: Mittel | O25: Keine Website | P25: Starterpaket | Q25: Local SEO Fix | R25: Neu | T25: Vor-Ort-Besuch | U25: Offen | V25: 1200 | W25: Alanya GO Yandex | X25: Oeffentlich gelistet
A26: B - Gute Chance | B26: 5 | C26: Saray | D26: Oemer Oezsoy Barber's Club | E26: Saray Mah Guelen Sok 20C | F26: Nicht gefunden | G26: Nicht gefunden | H26: Yandex Maps | I26: Nicht gefunden | J26: 4.0/5 (6) | K26: Herrenhaarschnitt Styling Bart | L26: Keine Website gefunden | M26: Kein Online-Booking gefunden | N26: Mittel | O26: Keine Website | P26: Starterpaket | Q26: Local SEO Fix | R26: Neu | T26: Vor-Ort-Besuch | U26: Offen | V26: 1000 | W26: Alanya GO | X26: Oeffentlich gelistet
A27: B - Gute Chance | B27: 5 | C27: Saray | D27: Yildiz Berber | E27: Saray Mah Abdullah Dogan Sok No:2D | F27: +90 533 773 03 70 | G27: Nicht gefunden | H27: Yandex Maps | I27: Nicht gefunden | J27: Yandex gelistet | K27: Sac kesimi traş sakal | L27: Keine Website gefunden | M27: Kein Online-Booking gefunden | N27: Mittel | O27: Keine Website | P27: Starterpaket | Q27: Local SEO Fix | R27: Neu | T27: Vor-Ort-Besuch | U27: Offen | V27: 1000 | W27: Yandex | X27: Oeffentlich gelistet
A28: B - Gute Chance | B28: 5 | C28: Saray | D28: Imran Kuafor | E28: Saray Mah Atatuerk Cad | F28: (0242) 513 99 59 | G28: Nicht gefunden | H28: Yelp | I28: Nicht gefunden | J28: Yelp gelistet | K28: Herrenhaarschnitt Bartpflege | L28: Keine Website gefunden | M28: Kein Online-Booking gefunden | N28: Mittel | O28: Keine Website | P28: Starterpaket | Q28: Local SEO Fix | R28: Neu | T28: Vor-Ort-Besuch | U28: Offen | V28: 800 | W28: Yelp | X28: Oeffentlich gelistet
A29: B - Gute Chance | B29: 5 | C29: Saray | D29: Konak Kuafor | E29: Saray Pelitlik Cd | F29: Nicht gefunden | G29: Nicht gefunden | H29: Alanya-GO | I29: Nicht gefunden | J29: 2.0/5 (1) | K29: Herrenhaarschnitt Bart | L29: Keine Website gefunden | M29: Kein Online-Booking gefunden | N29: Mittel | O29: Schwache Bewertung keine Praesenz | P29: Review-Mgmt + Website | Q29: Local SEO Fix | R29: Neu | T29: Spaeter pruefen | U29: Offen | V29: 600 | W29: Alanya GO | X29: Oeffentlich gelistet | Y29: Niedrige Bewertung
A30: B - Gute Chance | B30: 5 | C30: Saray | D30: Oezlem Erkek Kuafoerue | E30: Saray Hacihamdioğlu Cd 37 | F30: Nicht gefunden | G30: Nicht gefunden | H30: Yandex Maps | I30: Nicht gefunden | J30: Gelistet | K30: Herrenhaarschnitt | L30: Keine Website gefunden | M30: Kein Online-Booking gefunden | N30: Mittel | O30: Keine Website | P30: Starterpaket | Q30: Local SEO Fix | R30: Neu | T30: Vor-Ort-Besuch | U30: Offen | V30: 800 | W30: Yandex 07haber | X30: Oeffentlich gelistet
A31: B - Gute Chance | B31: 5 | C31: Saray | D31: Elite Erkek Kuafoerue | E31: Saray Yunus Emre Cd Onur Apt 31/D | F31: +90 535 395 77 85 | G31: Nicht gefunden | H31: Alanya-GO | I31: Nicht gefunden | J31: 5.0/5 (1) | K31: Herrenhaarschnitt | L31: Keine Website gefunden | M31: Kein Online-Booking gefunden | N31: Mittel | O31: Keine Website | P31: Starterpaket | Q31: Local SEO Fix | R31: Neu | T31: Vor-Ort-Besuch | U31: Offen | V31: 800 | W31: Alanya GO | X31: Oeffentlich gelistet
A32: B - Gute Chance | B32: 5 | C32: Saray | D32: Mehmet Oezen Sac Tasarim | E32: Saray Mah Kueluer Cad 13A | F32: Telefon auf Yandex | G32: Nicht gefunden | H32: Yandex Maps | I32: Nicht gefunden | J32: 4.6/5 (Yandex) | K32: Haardesign Herrenhaarschnitt | L32: Keine Website gefunden | M32: Kein Online-Booking gefunden | N32: Mittel | O32: Keine Website | P32: Starterpaket | Q32: Local SEO Fix | R32: Neu | T32: Vor-Ort-Besuch | U32: Offen | V32: 1000 | W32: Yandex | X32: Oeffentlich gelistet
A33: B - Gute Chance | B33: 5 | C33: Saray | D33: Ilarslan Hair Palace | E33: Saray Mah Guezel Yali Cad 26G | F33: +90 543 236 96 46 | G33: Nicht gefunden | H33: Yandex Maps | I33: YouTube Kanal | J33: 4.7/5 (10) | K33: Herren Extensions Color Keratin Naegel | L33: Keine Website gefunden | M33: Kein Online-Booking gefunden | N33: Mittel | O33: YouTube aktiv aber keine Website | P33: Website + Social Integration | Q33: Booking Upgrade | R33: Neu | T33: YouTube-Kanal analysieren | U33: Offen | V33: 1500 | W33: Yandex | X33: Oeffentlich gelistet | Y33: YouTube aktiv
A34: C - Spaeter | B34: 5 | C34: Saray | D34: By Berki Erkek Kuafoerue | E34: Alanya Merkez | F34: Nicht gefunden | G34: Nicht gefunden | H34: Yelp | I34: Nicht gefunden | J34: 5.0/5 (1) | K34: Herrenhaarschnitt Bart | L34: Keine Website gefunden | M34: Kein Online-Booking gefunden | N34: Mittel | O34: Nur 1 Review Adresse unklar | P34: Starterpaket | Q34: Nicht priorisiert | R34: Neu | T34: Spaeter pruefen | U34: Offen | V34: 500 | W34: Yelp | X34: Manuell zu pruefen | Y34: Adresse unklar
A35: C - Spaeter | B35: 5 | C35: Saray | D35: Favori Kuafor | E35: Alanya Merkez | F35: Nicht gefunden | G35: Nicht gefunden | H35: Yelp | I35: Nicht gefunden | J35: Yelp gelistet | K35: Herrenhaarschnitt Bart | L35: Keine Website gefunden | M35: Kein Online-Booking gefunden | N35: Niedrig | O35: Adresse unklar | P35: Spaeter evaluieren | Q35: Nicht priorisiert | R35: Neu | T35: Spaeter pruefen | U35: Offen | V35: 400 | W35: Yelp | X35: Manuell zu pruefen | Y35: Adresse unklar
A36: C - Spaeter | B36: 5 | C36: Saray | D36: Kuafoer Soner | E36: Alanya Merkez | F36: Nicht gefunden | G36: Nicht gefunden | H36: Yandex Maps | I36: Nicht gefunden | J36: 4.7/5 (21) | K36: Herren/Damen tiras | L36: Keine Website gefunden | M36: Kein Online-Booking gefunden | N36: Mittel | O36: Keine Website trotz guter Bewertungen | P36: Starterpaket | Q36: Nicht priorisiert | R36: Neu | T36: Spaeter pruefen | U36: Offen | V36: 800 | W36: Yandex | X36: Oeffentlich gelistet | Y36: Gute Bewertungen Adresse unklar
A37: B - Gute Chance | B37: 6 | C37: Cikcilli | D37: Mehmet Erkek Kuafoerue | E37: Cikcilli Mah 208 Sok No:2 | F37: +90 541 787 87 80 | G37: Nicht gefunden | H37: Yandex Maps | I37: Nicht gefunden | J37: Yandex gelistet | K37: Erkek sac kesimi traş sakal | L37: Keine Website gefunden | M37: Kein Online-Booking gefunden | N37: Mittel | O37: Keine Website | P37: Starterpaket | Q37: Local SEO Fix | R37: Neu | T37: Vor-Ort-Besuch | U37: Offen | V37: 1000 | W37: Yandex | X37: Oeffentlich gelistet
A38: B - Gute Chance | B38: 6 | C38: Cikcilli | D38: Mustafa Berber | E38: Cikcilli 206 Sokak 48 | F38: Nicht gefunden | G38: Nicht gefunden | H38: Barberhead | I38: Nicht gefunden | J38: 4.9/5 (13) | K38: Herrenhaarschnitt Bartpflege | L38: Keine Website gefunden | M38: Kein Online-Booking gefunden | N38: Mittel | O38: Sehr gute Bewertung keine Website | P38: Website + Google Business | Q38: Quick Win | R38: Neu | T38: Vor-Ort-Besuch | U38: Offen | V38: 1200 | W38: Barberhead | X38: Oeffentlich gelistet
A39: C - Spaeter | B39: 6 | C39: Cikcilli | D39: Dogan Berber | E39: Cikcilli Haci Baba Cd 17 | F39: Nicht gefunden | G39: Nicht gefunden | H39: Barberhead | I39: Nicht gefunden | J39: 5.0/5 (2) | K39: Herrenhaarschnitt Bartpflege | L39: Keine Website gefunden | M39: Kein Online-Booking gefunden | N39: Mittel | O39: Keine Website | P39: Starterpaket | Q39: Nicht priorisiert | R39: Neu | T39: Spaeter pruefen | U39: Offen | V39: 600 | W39: Barberhead | X39: Oeffentlich gelistet
A40: B - Gute Chance | B40: 7 | C40: Hacet | D40: EN Sac Tasarim Atoelyesi | E40: Bostancipinari Cd Hacet Mah No:124/A | F40: Nicht gefunden | G40: Nicht gefunden | H40: Barberhead | I40: Referenziert | J40: 5.0/5 (10) | K40: Cut Bart Color Pflege Massage | L40: Keine Website gefunden | M40: Kein Online-Booking gefunden | N40: Mittel | O40: Social Media aktiv keine Website | P40: Website + Social Integration | Q40: Booking Upgrade | R40: Neu | T40: Vor-Ort-Besuch | U40: Offen | V40: 1500 | W40: Barberhead Best of Alanya | X40: Oeffentlich gelistet | Y40: Seit 2009 Konzeptwechsel 2017
...

Sheet Route
B2: Field-Sales Route Plan - Alanya Barber Shops
B3: Optimierte Besuchsreihenfolge fuer Fussmarsch-Routen pro Bezirk
B5: Tag 1 - Vormittag: Sekerhane (8 Leads)
B6: Parken: | C6: Parkplatz Sekerhane Sevket Tokues Cad
B7: Leads: | C7: 8
B8: Top 5: | C8: 1. Kuafoer By Oezcan - 5.0* (92) 2. Ilyas Unver - Website seit 2010 3. Fi Still - 4.9* (27) 4. Keskin Makas - 5.0* 5. Mehmet Gabakci
B9: Route: | C9: Sevket Tokues Cad - Kaymakli Sok - Sipahioglu Sok - Kasapoglu Sok
B10: Notiz: | C10: Sehr dichte Konzentration. 5 Top-Leads in 400m. Alle ohne Website = hohe Conversion.
B12: Tag 1 - Nachmittag: Saray / Merkez (15 Leads)
B13: Parken: | C13: Cleopatra Beach Parkplatz
B14: Leads: | C14: 15
B15: Top 5: | C15: 1. Viking Hair Club - 4.9* Free Pick-up 2. Goelgen - 4.7* (347 Reviews) 3. Aydin Barbers - 5.0* (25) 4. Yilmaz Berber - Damlatas Cd 5. Mehmet Oezen
B16: Route: | C16: Cangal Sok - Damlatas Cd - Guelen Sok - Guezel Yali Cad - Kueluer Cad
B17: Notiz: | C17: Groesster Bezirk. Goelgen 347 Reviews = sehr bekannt. Viking ist Premium-Ziel.
B19: Tag 2 - Vormittag: Oba (5 Leads)
B20: Parken: | C20: Alanyum Shopping Mall Parkplatz
B21: Leads: | C21: 5
B22: Top 5: | C22: 1. Kerim Guven - 5.0* (254) Premium 2. Hair Studio Eyuep - 4.6* Coloring 3. Yusuf Berber - Website Instagram 4. Kardesler Berber 5. FK Kuafor
B23: Route: | C23: Carsamba Cad - Fabrika Cd - Karakues Sok - Eski Gazipasa Cd
B24: Notiz: | C24: Touristen-Bezirk. Kerim hat beste digitale Praesenz = Upsell-Ziel.
B26: Tag 2 - Nachmittag: Gueller Pınari (4 Leads)
B27: Parken: | C27: Gueller Pınari Mah Parkplatz
B28: Leads: | C28: 4
B29: Top 5: | C29: 1. Mavi Deniz - 4.9* (92) sehr beliebt 2. Prime Alanya - 5.0* Hausbesuch 3. Club Barber Tan 4. Bora Kuafor
B30: Route: | C30: Navalioglu Sok - Yildiz Sok - Yenilmez Cad - Hayate Hanim Cad
B31: Notiz: | C31: Mavi Deniz ist Top-Quick-Win: 92 Reviews keine Website.
B33: Tag 3 - Vormittag: Mahmutlar (3 Leads)
B34: Parken: | C34: Mahmutlar Merkez Atatuerk Cad
B35: Leads: | C35: 3
B36: Top 5: | C36: 1. King Barbershop - 5.0* Premium 2. Kuafor Tevfik - 4.4* 24h 3. Caglar Kuafor - 15+ Jahre
B37: Route: | C37: 119 St - 248 Sok - Cumhuriyet Mah
B38: Notiz: | C38: Tevfik 24h = einzigartig. King hat Website aber nur WhatsApp-Booking.
B40: Tag 3 - Nachmittag: Cikcilli (3 Leads)
B41: Parken: | C41: Cikcilli Merkez 206 Sokak
B42: Leads: | C42: 3
B43: Top 5: | C43: 1. Mustafa Berber - 4.9* (13) 2. Mehmet Erkek 3. Dogan Berber
B44: Route: | C44: 208 Sok - 206 Sokak - Haci Baba Cd
B45: Notiz: | C45: Kleiner Bezirk schnell abzuarbeiten. Mustafa sehr gute Bewertungen.
B47: Tag 4: Hacet + Kizlar Pınari (5 Leads)
B48: Parken: | C48: Hacet Bostancipinari Cad
...

Sheet Token-Kostenrechner
B2: Token-Kostenrechner - Aktuelle Modelle Juni 2026
B3: Nur aktuelle Frontier-Modelle | Alle Preise verifiziert Juni 2026 | Blaue Felder = editierbar
B4: EUR/USD: | C4: 0.93
B6: 1. Aktuelle API-Preise pro 1 Million Tokens | Stand 25. Juni 2026
B7: Modell | C7: Anbieter | D7: Input $/1M | E7: Output $/1M | F7: Cached $/1M | G7: Input EUR/1M | H7: Output EUR/1M | I7: Kontext | J7: Release | K7: Best fuer
B8: Claude Opus 4.8 | C8: Anthropic | D8: 5 | E8: 25 | F8: 0.5 | G8: =D8*$C$4 -> 4.65 | H8: =E8*$C$4 -> 23.25 | I8: 1M | J8: Mai 2026 | K8: Beste Qualitaet, Coding, Agenten
B9: GPT-5.5 Pro | C9: OpenAI | D9: 30 | E9: 180 | F9: 0.5 | G9: =D9*$C$4 -> 27.9 | H9: =E9*$C$4 -> 167.4 | I9: 1M | J9: Juni 2026 | K9: Ultra-Premium, komplexeste Aufgaben
B10: GPT-5.5 | C10: OpenAI | D10: 5 | E10: 30 | F10: 0.5 | G10: =D10*$C$4 -> 4.65 | H10: =E10*$C$4 -> 27.9 | I10: 1M (400K Codex) | J10: Mai 2026 | K10: Flagship, Agenten, Reasoning
B11: Claude Sonnet 4.6 | C11: Anthropic | D11: 3 | E11: 15 | F11: 0.3 | G11: =D11*$C$4 -> 2.79 | H11: =E11*$C$4 -> 13.95 | I11: 1M | J11: Mai 2026 | K11: Bestes Preis-Leistung, Coding
B12: GPT-5.4 | C12: OpenAI | D12: 2.5 | E12: 15 | F12: 0.25 | G12: =D12*$C$4 -> 2.325 | H12: =E12*$C$4 -> 13.95 | I12: 400K | J12: Aug 2025 | K12: General-Purpose, gute Balance
B13: DeepSeek V4 Pro | C13: DeepSeek | D13: 0.435 | E13: 0.87 | F13: 0.0036 | G13: =D13*$C$4 -> 0.40455 | H13: =E13*$C$4 -> 0.8091 | I13: 1M | J13: Juni 2026 | K13: Guenstigster, 80.6% SWE-bench
B16: 2. Projekt-Schaetzer - Wie viel kostet meine Anforderung?
B17: So funktionierts: Waehlen Sie ein Modell (Zeile 8-13), schaetzen Sie Tokens in Millionen, Excel rechnet.
B18: Projekt / Anforderung | C18: Modell (Zeile) | D18: Input Mio | E18: Output Mio | F18: Cached Mio | G18: Input-Kosten | H18: Output-Kosten | I18: Cached-Kosten | J18: GESAMT | K18: Sicherheit
B19: CRM: Neue Lead-Seite erstellen | C19: =B10 -> GPT-5.5 | D19: 0.5 | E19: 0.15 | F19: 0.2 | G19: =D19*G10 -> 2.325 | H19: =E19*H10 -> 4.185 | I19: =F19*F10*$C$4 -> 0.093 | J19: =G19+H19+I19 -> 6.603 | K19: Schaetzung
B20: Landingpage: Tuerkisch uebersetzen | C20: =B10 -> GPT-5.5 | D20: 0.8 | E20: 0.3 | F20: 0.4 | G20: =D20*G10 -> 3.72 | H20: =E20*H10 -> 8.37 | I20: =F20*F10*$C$4 -> 0.186 | J20: =G20+H20+I20 -> 12.276 | K20: Schaetzung
B21: AI-Chat: Barber-Intents trainieren | C21: =B10 -> GPT-5.5 | D21: 2 | E21: 0.5 | F21: 1 | G21: =D21*G10 -> 9.3 | H21: =E21*H10 -> 13.95 | I21: =F21*F10*$C$4 -> 0.465 | J21: =G21+H21+I21 -> 23.715 | K21: Unsicher
B22: SEO: 50 Barbieren analysieren | C22: =B13 -> DeepSeek V4 Pro | D22: 0.3 | E22: 0.1 | F22: 0.1 | G22: =D22*G13 -> 0.121365 | H22: =E22*H13 -> 0.08091 | I22: =F22*F13*$C$4 -> 0.0003348 | J22: =G22+H22+I22 -> 0.2026098 | K22: Erfahrungswert
B23: Template: 5-Seiten Barber-Website | C23: =B9 -> GPT-5.5 Pro | D23: 1.5 | E23: 0.8 | F23: 0.5 | G23: =D23*G9 -> 41.85 | H23: =E23*H9 -> 133.92 | I23: =F23*F9*$C$4 -> 0.2325 | J23: =G23+H23+I23 -> 176.0025 | K23: Schaetzung
B24: Review-Monitoring automatisieren | C24: =B13 -> DeepSeek V4 Pro | D24: 0.2 | E24: 0.05 | F24: 0.05 | G24: =D24*G13 -> 0.08091 | H24: =E24*H13 -> 0.040455 | I24: =F24*F13*$C$4 -> 0.0001674 | J24: =G24+H24+I24 -> 0.1215324 | K24: Erfahrungswert
B25: GESAMT | J25: =SUM(J19:J24) -> 218.92064
B27: 3. Schnell-Referenz: Wie viele Tokens braucht man fuer...?
B28: Einfacher Bug-Fix | D28: ~400K Input / ~10K Output | F28: ~25 API-Calls, 75% Cache
B29: Neues Feature implementieren | D29: ~2M Input / ~40K Output | F29: ~100 Calls, 80% Cache
B30: Webseite uebersetzen (TR-DE) | D30: ~500K Input / ~200K Output | F30: ~10 API-Calls
B31: AI-Chat Training (50 Intents) | D31: ~1-3M Input / ~200K Output | F31: Batch-Verarbeitung
B32: SEO-Analyse pro Website | D32: ~50K Input / ~5K Output | F32: ~1 API-Call
B33: Code-Review einer Datei | D33: ~100K Input / ~20K Output | F33: ~5 API-Calls
B34: Landingpage HTML/CSS erstellen | D34: ~300K Input / ~100K Output | F34: ~20 API-Calls
B36: Quellen der Preisdaten
B37: - Anthropic API Pricing (anthropic.com/pricing) - Stand 25. Juni 2026
B38: - OpenAI API Pricing (openai.com/pricing) - Stand 25. Juni 2026
B39: - PricePerToken.com - Stand 25. Juni 2026
B40: - MorphLLM AI Coding Costs (morphllm.com) - Stand 18. Juni 2026
B41: - SurePrompts AI Models 2026 (sureprompts.com) - Stand 17. Juni 2026

Sheet Angebot & Umsatz
B2: Angebot & Umsatz
B4: 1. Verkaufspakete
B5: Starter | C5: 5-Seiten Website + Google Business + WhatsApp + SEO | F5: 150 | G5: 7950 | H5: Kleine Barbiere
B6: Professional | C6: Multi-Lingual + Booking + AI-Chat + SEO/GEO | F6: 470 | G6: 24910 | H6: Mittlere/Touristen
B7: Premium | C7: Alles aus Pro + Review-Mgmt + Analytics + VIP | F7: 755 | G7: 40015 | H7: Grosse Salons
B9: 2. Kosten & Marge - EDITIERBAR
B10: Paket | C10: Dev-Stunden | D10: Stundensatz | E10: Dev-Kosten | F10: Sonstige | G10: Gesamt-Kosten | H10: VK-Preis | I10: Marge | J10: Marge %
B11: Starter | C11: 12 | D11: 50 | E11: =C11*D11 -> 600 | F11: 30 | G11: =E11+F11 -> 630 | H11: 150 | I11: =H11-G11 -> -480 | J11: =IF(H11>0,I11/H11,"") -> -3.2
B12: Professional | C12: 35 | D12: 50 | E12: =C12*D12 -> 1750 | F12: 80 | G12: =E12+F12 -> 1830 | H12: 470 | I12: =H12-G12 -> -1360 | J12: =IF(H12>0,I12/H12,"") -> -2.893617
B13: Premium | C13: 55 | D13: 50 | E13: =C13*D13 -> 2750 | F13: 120 | G13: =E13+F13 -> 2870 | H13: 755 | I13: =H13-G13 -> -2115 | J13: =IF(H13>0,I13/H13,"") -> -2.8013245
B15: 3. Umsatz-Prognose
B16: Leads gesamt | D16: 50
B17: Conversion Rate | D17: 0.15
B18: Deal-Wert EUR | D18: 350
B19: Monatlich/Kunde EUR | D19: 45
B20: Monate | D20: 12
B21: Geschlossene Deals | D21: =D16*D17 -> 7.5
B22: Einmaliger Umsatz | D22: =D21*D18 -> 2625
B23: Wiederkehrend J1 | D23: =D21*D19*D20 -> 4050
B24: GESAMT JAHR 1 | D24: =D22+D23 -> 6675

Sheet Landingpage TR
B2: Landing Page Content - Tuerkisch (TR)
B5: HERO HEADLINE
B6: Ana: Daha Fazla Musteri, Daha Az Bekleme - Dijital Berberlik Alt: Alanya'da Berber ve Kuafoerler Icin Oezel Dijital Coezuemler
B8: PAIN POINTS
B9: - Telefon suerekli caliyor, randevu icin sekreter yok - Turist musteriler dil bariyeri yuezunden baska yere gidiyor - Instagram'da guzel fotograf var ama musteri doenuesuemue yok - Google'da araniyorsunuz ama web siteniz yok - Mesai saatleri disinda randevu alinamiyor - Rakipleriniz Booking.com kullaniyor - siz hala kagit defter
B11: PAKET 1 - BASLANGIC
B12: - Modern mobil uyumlu web sitesi (5 sayfa) - Google Isletme Profili kurulum - WhatsApp randevu butonu - Temel SEO Fiyat: 5.000-8.000 TL (95-150 EUR)
B14: PAKET 2 - PROFESYONEL
B15: - Coek dilli web sitesi (TR+EN+RU/DE) - Online randevu sistemi - AI chat asistan (7/24) - Foto galerisi - Gelismis SEO+GEO Fiyat: 15.000-25.000 TL (285-470 EUR)
B17: PAKET 3 - PREMIUM
B18: - Tam oezellikli web sitesi + randevu + AI chat - Instagram entegrasyonu - Yorum yoenetimi - Aylik SEO raporu Fiyat: 25.000-40.000 TL (470-755 EUR)
B20: BEFORE/AFTER
... B36: Sayfa yapisi: Hero + Pain Points + Before/After + 3 Paket + Randevu Demo + AI Chat Demo + Google Goesterimi + Trust + Harita + FAQ + CTA Footer Renk: Lacivert #1B3A5C, Altin #D4A843, Yesil #2E7D32 Teknoloji: Next.js, Responsive, SSR SEO

Sheet Quellen & Annahmen
B2: Quellen & Annahmen
B4: Thema | C4: Quelle | D4: Link | E4: Genutzte Daten | F4: Vertrauen | G4: Geprueft | H4: Kommentar
B5: Alanya Nuefus | C5: TUIK 2024 | D5: mansetalanya.com | E5: Mahalle bazli nuefus | F5: Hoch | G5: 2026-06 | H5: Resmi istatistik
B6: Alanya Turizm | C6: ALTID | D6: altid.org.tr | E6: 4.5-5 milyon yillik turist | F6: Hoch | G6: 2026-06 | H6: Turizm dernegi
B7: Esnaf Istatistik | C7: TESK | D7: esnafkoop.ticaret.gov.tr | E7: 2.55M esnaf | F7: Hoch | G7: 2026-06 | H7: Resmi konfederasyon
B8: Berber Fiyat 2025 | C8: Antalya Berberler Odasi | D8: atonet.org.tr | E8: 2025 tarife | F8: Hoch | G8: 2026-06 | H8: Resmi oda
B9: Barber Listeleri | C9: Yandex Maps | D9: yandex.com.tr/maps | E9: Isletme listeleri | F9: Mittel | G9: 2026-06 | H9: Kullanici degerlendirmeleri
B10: Barber Listeleri | C10: Barberhead | D10: barberhead.com/alanya | E10: Premium berber listesi | F10: Mittel | G10: 2026-06 | H10: Sektorel dizin
B11: Barber Listeleri | C11: Alanya GO | D11: alanya-go.com | E11: Isletme listeleri | F11: Mittel | G11: 2026-06 | H11: Yerel rehber
B12: Token Preise | C12: Anthropic API | D12: anthropic.com/pricing | E12: Claude Opus 4.8 $5/$25 | F12: Hoch | G12: 2026-06-25 | H12: Resmi API pricing
B13: Token Preise | C13: OpenAI API | D13: openai.com/pricing | E13: GPT-5.5 Pro $30/$180 | F13: Hoch | G13: 2026-06-25 | H13: Resmi API pricing
B14: Token Preise | C14: PricePerToken | D14: pricepertoken.com | E14: Vergleichstabellen | F14: Hoch | G14: 2026-06-25 | H14: Aggregator
B15: Token Preise | C15: MorphLLM | D15: morphllm.com | E15: AI Coding Costs Benchmarks | F15: Hoch | G15: 2026-06-18 | H15: Benchmark-Report
... B18: Doviz Kuru | C18: ECB | D18: ecb.europa.eu | E18: ~0.93 EUR/USD | F18: Hoch | G18: 2026-06 | H18: ECB resmi
B21: Wichtige Annahmen
B22: 1. BERBER SAYISI: 250-450 Barbieren basiert auf TESK-Ratios. Keine offizielle Liste verfuegbar.
B23: 2. WEBSITE-ADOPTION: 80-90% ohne Website = Schaetzung (45/50 = 90% in Stichprobe).
B24: 3. TOKEN-PREISE: Alle Preise sind oeffentliche API-Preise (25. Juni 2026). Subscription-Plaene (Claude Pro $20/mo) koennen guenstiger sein.
B25: 4. GPT-5.5 PRO: $30/$180 ist der hoechste oeffentliche API-Preis. Fuer die meisten CRM-Aufgaben ist Sonnet 4.6 oder GPT-5.4 ausreichend.
B26: 5. CONVERSION-RATE: 15% ist ein B2B-Industriestandard, nicht spezifisch verifiziert.
B27: 6. OFFIZIELLE LISTEN: Weder Alanya Belediyesi noch ALESO veroeffentlichen Online-Mitgliederlisten.
B28: 7. BEWERTUNGEN: Stammen von oeffentlichen Plattformen - nicht unabhaengig geprueft.
B29: 8. DeepSeek V4 Pro: Preise gelten fuer Serverless-API. Viele Provider quantisieren auf fp8 was Qualitaet mindert.
